# app/services/security_service.py

from datetime import datetime, timedelta
from fastapi import Depends, HTTPException, status
from fastapi.security import OAuth2PasswordBearer
from jose import JWTError, jwt
from passlib.context import CryptContext
from sqlalchemy.orm import Session

from db import database, models
# --- CORRECTED IMPORT ---
from models import schemas

# ... (rest of the file is mostly the same)
pwd_context = CryptContext(schemes=["bcrypt"], deprecated="auto")
SECRET_KEY = "a_very_secret_key_change_this_in_production"
ALGORITHM = "HS256"
ACCESS_TOKEN_EXPIRE_MINUTES = 30

oauth2_scheme = OAuth2PasswordBearer(tokenUrl="/auth/token")

def verify_password(plain_password: str, hashed_password: str) -> bool:
    return pwd_context.verify(plain_password, hashed_password)

def get_password_hash(password: str) -> str:
    return pwd_context.hash(password)

def create_access_token(data: dict, expires_delta: timedelta | None = None) -> str:
    # ...
    to_encode = data.copy()
    if expires_delta:
        expire = datetime.utcnow() + expires_delta
    else:
        expire = datetime.utcnow() + timedelta(minutes=15)
    to_encode.update({"exp": expire})
    encoded_jwt = jwt.encode(to_encode, SECRET_KEY, algorithm=ALGORITHM)
    return encoded_jwt

def get_current_user(token: str = Depends(oauth2_scheme), db: Session = Depends(database.get_db)) -> models.User:
    credentials_exception = HTTPException(
        status_code=status.HTTP_401_UNAUTHORIZED,
        detail="Could not validate credentials",
        headers={"WWW-Authenticate": "Bearer"},
    )
    try:
        payload = jwt.decode(token, SECRET_KEY, algorithms=[ALGORITHM])
        username: str = payload.get("sub")
        if username is None:
            raise credentials_exception
        # --- CORRECTED MODEL USAGE ---
        token_data = schemas.TokenData(username=username)
    except JWTError:
        raise credentials_exception
    
    user = db.query(models.User).filter(models.User.username == token_data.username).first()
    if user is None:
        raise credentials_exception
    return user